Workbook

Sheet MDS
A1: Especies | B1: MDS1 | C1: MDS2 | D1: group$ | E1: pc1xDM | F1: fisherpc1DM | G1: pc2xDM | H1: fisherpc2DM | I1: pc3xDM | J1: fisherpc3DM | K1: pc4xDM | L1: fisherpc4DM
A2: Cercocebus_agilis | B2: 0.34952679 | C2: -1.905893 | D2: Cata | E2: 0.97208867 | F2: 2.1289079 | G2: 0.057279086 | H2: 0.057341852 | I2: 0.090732751 | J2: 0.090982971 | K2: 0.040932082 | L2: 0.040954965
A3: Cercocebus_torquatus | B3: -2.6886634 | C3: -1.5184778 | D3: Cata | E3: 0.9610362 | F3: 1.9592977 | G3: 0.17668228 | H3: 0.17855598 | I3: 0.033192829 | J3: 0.033205027 | K3: 0.060420846 | L3: 0.060494534
A4: Cercopithecus_ascanius | B4: -0.6634824 | C4: 1.5267536 | D4: Cata | E4: 0.91879624 | F4: 1.5812459 | G4: 0.065879393 | H4: 0.065974949 | I4: 0.11341955 | J4: 0.11390968 | K4: 0.1007399 | L4: 0.10108278
A5: Cercopithecus_campbelli | B5: -4.1055763 | C5: -0.29520283 | D5: Cata | E5: 0.93167283 | F5: 1.6709171 | G5: 0.02183641 | H5: 0.021839882 | I5: 0.052330097 | J5: 0.052377943 | K5: 0.11745231 | L5: 0.11799691
A6: Cercopithecus_cephus | B6: -4.2892419 | C6: -1.2594717 | D6: Cata | E6: 0.94598837 | F6: 1.7921629 | G6: 0.018167296 | H6: 0.018169296 | I6: 0.015172436 | J6: 0.0151736 | K6: 0.022579832 | L6: 0.022583671
A7: Cercopithecus_diana | B7: -3.5101845 | C7: -1.0810654 | D7: Cata | E7: 0.93798439 | F7: 1.7210088 | G7: 0.11417663 | H7: 0.11467669 | I7: 0.0058551858 | J7: 0.0058552527 | K7: 0.081076246 | L7: 0.081254598
A8: Cercopithecus_mitis | B8: -4.0343011 | C8: -1.201553 | D8: Cata | E8: 0.95139134 | F8: 1.8462481 | G8: 0.032966291 | H8: 0.032978241 | I8: 0.038104559 | J8: 0.038123017 | K8: 0.1065659 | L8: 0.10697207
A9: Cercopithecus_neglectus | B9: 7.2934815 | C9: 3.0721741 | D9: Cata | E9: 0.96459666 | F9: 2.0081181 | G9: 0.024300347 | H9: 0.024305132 | I9: 0.0081674036 | J9: 0.0081675852 | K9: 0.048818109 | L9: 0.048856946
A10: Cercopithecus_nictitans | B10: -3.4621929 | C10: 1.6981501 | D10: Cata | E10: 0.9559107 | F10: 1.896197 | G10: 0.036484754 | H10: 0.036500956 | I10: 0.0035380677 | J10: 0.0035380825 | K10: 0.046803025 | L10: 0.046837245
A11: Chlorocebus_aethiops | B11: 0.057527724 | C11: -1.6151138 | D11: Cata | E11: 0.96924619 | F11: 2.079696 | G11: 0.051754114 | H11: 0.051800396 | I11: 0.012712147 | J11: 0.012712832 | K11: 0.052201481 | L11: 0.052248975
A12: Colobus_angolensis | B12: -2.7600478 | C12: -1.4498801 | D12: Cata | E12: 0.86669531 | F12: 1.3196438 | G12: 0.2283145 | H12: 0.23241055 | I12: 0.11029653 | J12: 0.11074708 | K12: 0.10902937 | L12: 0.10946451
A13: Colobus_guereza | B13: -2.765581 | C13: -1.4516877 | D13: Cata | E13: 0.96263317 | F13: 1.9806294 | G13: 0.037832836 | H13: 0.037850902 | I13: 0.051057243 | J13: 0.051101678 | K13: 0.045662788 | L13: 0.045694565
... A65: Saimiri_sciureus | B65: -1.3664339 | C65: -1.8430496 | D65: Platy | E65: 0.90910884 | F65: 1.5223645 | G65: 0.22586341 | H65: 0.22982619 | I65: 0.0945653 | J65: 0.094848709 | K65: 0.15905144 | L65: 0.16041337

Sheet W matrices
A1: W NWM | DZ1: Autovalores | EA1: Autovetores
B2: 0.28788201 | C2: 0 | D2: 0 | E2: 0 | F2: 0 | G2: 0 | H2: 0 | I2: 0 | J2: 0 | K2: 0 | L2: 0 | M2: 0 | N2: 0 | O2: 0 | P2: 0 | Q2: 0 | R2: 0 | S2: 0 | T2: 0 | U2: 0 | V2: 0 | W2: 0 | X2: 0 | Y2: 0 | Z2: 0 | AA2: 0 | AB2: 0 | AC2: 0 | AD2: 0 | AE2: 0 | AF2: 0 | AG2: 0 | AH2: 0 | AI2: 0 | AJ2: 0 | AK2: 0 | AL2: 0 | AM2: 0 | AN2: 0 | AQ2: 0.28788201 | AR2: 0.29577533 | AS2: 0.52556544 | AT2: 0.19094259 | AU2: 0.22925861 | AV2: 0.23435357 | AW2: 0.08156975 | AX2: 0.22559868 | AY2: 0.35352581 | AZ2: 0.26921205 | BA2: 0.22315948 | BB2: 0.23538403 | BC2: 0.14482896 | BD2: 0.088960172 | BE2: 0.173228 | BF2: 0.15150791 | BG2: 0.32035219 | BH2: 0.22512874 | BI2: 0.22869586 | BJ2: 0.06888546 | BK2: 0.079856382 | BL2: 0.31227038 | BM2: 0.14618714 | BN2: 0.17072622 | BO2: 0.28132814 | BP2: 0.2832201 | BQ2: 0.15808195 | BR2: 0.24606758 | BS2: 0.17948043 | BT2: 0.08208066 | BU2: 0.18941174 | BV2: 0.22308558 | BW2: 0.21949511 | BX2: 0.10879614 | BY2: 0.13496531 | BZ2: 0.094750917 | CA2: 0.28824248 | CB2: 0.15078325 | CC2: 0.032221882 | CJ2: 0.28788201 | CK2: 0.29577533 | CL2: 0.52556544 | CM2: 0.19094259 | CN2: 0.22925861 | CO2: 0.23435357 | CP2: 0.08156975 | CQ2: 0.22559868 | CR2: 0.35352581 | CS2: 0.26921205 | CT2: 0.22315948 | CU2: 0.23538403 | CV2: 0.14482896 | CW2: 0.088960172 | CX2: 0.173228 | CY2: 0.15150791 | CZ2: 0.32035219 | DA2: 0.22512874 | DB2: 0.22869586 | DC2: 0.06888546 | DD2: 0.079856382 | DE2: 0.31227038 | DF2: 0.14618714 | DG2: 0.17072622 | DH2: 0.28132814 | DI2: 0.2832201 | DJ2: 0.15808195 | DK2: 0.24606758 | DL2: 0.17948043 | DM2: 0.08208066 | DN2: 0.18941174 | DO2: 0.22308558 | DP2: 0.21949511 | DQ2: 0.10879614 | DR2: 0.13496531 | DS2: 0.094750917 | DT2: 0.28824248 | DU2: 0.15078325 | DV2: 0.032221882 | DY2: Pc1 | DZ2: 21.055275 | EA2: 0.062099753 | EB2: 0.13014064 | EC2: 0.22234112 | ED2: 0.15289651 | EE2: 0.17098693 | EF2: 0.12103849 | EG2: 0.076366945 | EH2: 0.11887911 | EI2: 0.21051194 | EJ2: 0.21270414 | EK2: 0.1211035 | EL2: 0.16887427 | EM2: 0.12164198 | EN2: 0.11925752 | EO2: 0.033286418 | EP2: 0.19750947 | EQ2: 0.31990284 | ER2: 0.26139319 | ES2: 0.28030662 | ET2: 0.15666048 | EU2: 0.056960844 | EV2: 0.21808215 | EW2: 0.11266509 | EX2: 0.11841584 | EY2: 0.18639489 | EZ2: 0.21037724 | FA2: 0.087880713 | FB2: 0.14641225 | FC2: 0.13118178 | FD2: 0.045440761 | FE2: 0.12081288 | FF2: 0.13916351 | FG2: 0.16321458 | FH2: 0.053008167 | FI2: 0.066668716 | FJ2: 0.071244884 | FK2: 0.28281374 | FL2: 0.094452909 | FM2: 0.0096500671
B3: 0.29577533 | C3: 1.4976137 | AQ3: 0 | AR3: 1.4976137 | AS3: 0.97195511 | AT3: 0.70101888 | AU3: 0.61157404 | AV3: 0.45003988 | AW3: -0.21364916 | AX3: 0.24784203 | AY3: 0.60701966 | AZ3: 0.41966795 | BA3: 0.39101128 | BB3: 0.49117256 | BC3: 0.18400557 | BD3: 0.20169018 | BE3: 0.43393911 | BF3: 0.20717132 | BG3: 0.58509222 | BH3: 0.42200266 | BI3: 0.52934194 | BJ3: 0.086711415 | BK3: 0.25421859 | BL3: 0.771932 | BM3: 0.27963989 | BN3: 0.41055022 | BO3: 0.67226819 | BP3: 0.72454799 | BQ3: 0.33001503 | BR3: 0.66062078 | BS3: 0.39551287 | BT3: 0.084466012 | BU3: 0.3168544 | BV3: 0.56836818 | BW3: 0.55420368 | BX3: 0.04520859 | BY3: 0.2099546 | BZ3: -0.024504149 | CA3: 0.56575177 | CB3: 0.18940813 | CC3: 0.031877153 | CJ3: 0.29577533 | CK3: 1.4976137 | CL3: 0.97195511 | CM3: 0.70101888 | CN3: 0.61157404 | CO3: 0.45003988 | CP3: -0.21364916 | CQ3: 0.24784203 | CR3: 0.60701966 | CS3: 0.41966795 | CT3: 0.39101128 | CU3: 0.49117256 | CV3: 0.18400557 | CW3: 0.20169018 | CX3: 0.43393911 | CY3: 0.20717132 | CZ3: 0.58509222 | DA3: 0.42200266 | DB3: 0.52934194 | DC3: 0.086711415 | DD3: 0.25421859 | DE3: 0.771932 | DF3: 0.27963989 | DG3: 0.41055022 | DH3: 0.67226819 | DI3: 0.72454799 | DJ3: 0.33001503 | DK3: 0.66062078 | DL3: 0.39551287 | DM3: 0.084466012 | DN3: 0.3168544 | DO3: 0.56836818 | DP3: 0.55420368 | DQ3: 0.04520859 | DR3: 0.2099546 | DS3: -0.024504149 | DT3: 0.56575177 | DU3: 0.18940813 | DV3: 0.031877153 | DY3: PC2 | DZ3: 8.4418858 | EA3: 0.01230248 | EB3: 0.017436116 | EC3: 0.041574886 | ED3: 0.023134787 | EE3: 0.028237828 | EF3: 0.034373793 | EG3: 0.0010029077 | EH3: 0.011105899 | EI3: 0.029511961 | EJ3: 0.53712555 | EK3: 0.012366716 | EL3: 0.02536809 | EM3: 0.39853125 | EN3: 0.12962132 | EO3: 0.13346641 | EP3: -0.13806321 | EQ3: -0.13749065 | ER3: -0.1502982 | ES3: -0.17836541 | ET3: -0.18563089 | EU3: -0.0019787545 | EV3: 0.025240452 | EW3: 0.022837284 | EX3: 0.016074334 | EY3: 0.0029434842 | EZ3: 0.0092405994 | FA3: 0.012127308 | FB3: 0.0065724601 | FC3: -0.00087460014 | FD3: 0.014636053 | FE3: 0.020729421 | FF3: 0.018434132 | FG3: 0.0030042413 | FH3: 0.097971369 | FI3: -0.58365565 | FJ3: 0.144597 | FK3: -0.10317527 | FL3: 0.0081266682 | FM3: 0.01288237
B4: 0.52556544 | C4: 0.97195511 | D4: 2.4674588 | AQ4: 0 | AR4: 0 | AS4: 2.4674588 | AT4: 0.97906396 | AU4: 1.1059457 | AV4: 0.9492222 | AW4: 0.39493442 | AX4: 0.68021466 | AY4: 1.1813304 | AZ4: 0.82781401 | BA4: 0.67492121 | BB4: 1.0775111 | BC4: 0.4473199 | BD4: 0.33282697 | BE4: 0.58713485 | BF4: 0.52058989 | BG4: 1.1318878 | BH4: 0.78523229 | BI4: 0.81560533 | BJ4: 0.21319549 | BK4: 0.24826763 | BL4: 1.1066465 | BM4: 0.62180616 | BN4: 0.57884508 | BO4: 0.98216086 | BP4: 1.0818818 | BQ4: 0.5298517 | BR4: 0.18208902 | BS4: 0.63284749 | BT4: 0.19791445 | BU4: 0.64536092 | BV4: 0.7313321 | BW4: 0.79402954 | BX4: 0.39209742 | BY4: 0.43042457 | BZ4: 0.34889442 | CA4: 0.96629306 | CB4: 0.49681075 | CC4: 0.085031804 | CJ4: 0.52556544 | CK4: 0.97195511 | CL4: 2.4674588 | CM4: 0.97906396 | CN4: 1.1059457 | CO4: 0.9492222 | CP4: 0.39493442 | CQ4: 0.68021466 | CR4: 1.1813304 | CS4: 0.82781401 | CT4: 0.67492121 | CU4: 1.0775111 | CV4: 0.4473199 | CW4: 0.33282697 | CX4: 0.58713485 | CY4: 0.52058989 | CZ4: 1.1318878 | DA4: 0.78523229 | DB4: 0.81560533 | DC4: 0.21319549 | DD4: 0.24826763 | DE4: 1.1066465 | DF4: 0.62180616 | DG4: 0.57884508 | DH4: 0.98216086 | DI4: 1.0818818 | DJ4: 0.5298517 | DK4: 0.18208902 | DL4: 0.63284749 | DM4: 0.19791445 | DN4: 0.64536092 | DO4: 0.7313321 | DP4: 0.79402954 | DQ4: 0.39209742 | DR4: 0.43042457 | DS4: 0.34889442 | DT4: 0.96629306 | DU4: 0.49681075 | DV4: 0.085031804 | DZ4: 7.6284905 | EA4: -0.049114869 | EB4: -0.14017355 | EC4: -0.1917338 | ED4: -0.15524581 | EE4: -0.1528162 | EF4: -0.09153793 | EG4: -0.044524651 | EH4: -0.092209614 | EI4: -0.15610194 | EJ4: 0.11218972 | EK4: -0.064166622 | EL4: -0.087946061 | EM4: 0.11688394 | EN4: 0.010839042 | EO4: -0.35992727 | EP4: 0.29314595 | EQ4: 0.23490499 | ER4: 0.26217368 | ES4: 0.21698326 | ET4: 0.37403411 | EU4: 0.0090398129 | EV4: -0.12698509 | EW4: -0.083705966 | EX4: -0.086333953 | EY4: -0.064695795 | EZ4: -0.18180004 | FA4: -0.052094774 | FB4: -0.10914211 | FC4: -0.067813795 | FD4: -0.0097675164 | FE4: -0.044850802 | FF4: -0.13876816 | FG4: -0.12662544 | FH4: 0.0024573519 | FI4: -0.36484787 | FJ4: 0.05237169 | FK4: 0.1534536 | FL4: -0.044222311 | FM4: -1.1679504e-05
B5: 0.19094259 | C5: 0.70101888 | D5: 0.97906396 | E5: 1.378421 | AQ5: 0 | AR5: 0 | AS5: 0 | AT5: 1.378421 | AU5: 0.91820281 | AV5: 0.57603503 | AW5: 0.44761389 | AX5: 0.86293525 | AY5: 0.81851636 | AZ5: 0.56275642 | BA5: 0.50464835 | BB5: 0.58141 | BC5: 0.28381878 | BD5: 0.27118553 | BE5: 0.38984386 | BF5: 0.27857859 | BG5: 0.69432571 | BH5: 0.50160527 | BI5: 0.60497673 | BJ5: 0.10542846 | BK5: -0.18831637 | BL5: 0.77889403 | BM5: 0.3319135 | BN5: 0.46392601 | BO5: 0.6049039 | BP5: 0.75003197 | BQ5: 0.33987703 | BR5: 0.6757587 | BS5: 0.46499594 | BT5: 0.14445926 | BU5: 0.37293839 | BV5: 0.58648265 | BW5: 0.61082471 | BX5: 0.16264634 | BY5: 0.35154471 | BZ5: 0.14597289 | CA5: 0.65087992 | CB5: 0.29121547 | CC5: -0.0034823844 | CJ5: 0.19094259 | CK5: 0.70101888 | CL5: 0.97906396 | CM5: 1.378421 | CN5: 0.91820281 | CO5: 0.57603503 | CP5: 0.44761389 | CQ5: 0.86293525 | CR5: 0.81851636 | CS5: 0.56275642 | CT5: 0.50464835 | CU5: 0.58141 | CV5: 0.28381878 | CW5: 0.27118553 | CX5: 0.38984386 | CY5: 0.27857859 | CZ5: 0.69432571 | DA5: 0.50160527 | DB5: 0.60497673 | DC5: 0.10542846 | DD5: -0.18831637 | DE5: 0.77889403 | DF5: 0.3319135 | DG5: 0.46392601 | DH5: 0.6049039 | DI5: 0.75003197 | DJ5: 0.33987703 | DK5: 0.6757587 | DL5: 0.46499594 | DM5: 0.14445926 | DN5: 0.37293839 | DO5: 0.58648265 | DP5: 0.61082471 | DQ5: 0.16264634 | DR5: 0.35154471 | DS5: 0.14597289 | DT5: 0.65087992 | DU5: 0.29121547 | DV5: -0.0034823844 | DZ5: 3.8851927 | EA5: 0.00063774341 | EB5: 0.14029895 | EC5: -0.047451448 | ED5: -0.00160186 | EE5: -0.18937457 | EF5: -0.085485135 | EG5: -0.074139307 | EH5: -0.039094522 | EI5: -0.16343979 | EJ5: 0.013951404 | EK5: -0.013104414 | EL5: -0.054607278 | EM5: -0.23149741 | EN5: -0.23627701 | EO5: 0.10384848 | EP5: -0.052301549 | EQ5: -0.041171728 | ER5: 0.018884996 | ES5: 0.20668412 | ET5: 0.0062919457 | EU5: 0.089074089 | EV5: 0.079318333 | EW5: -0.13708209 | EX5: -0.00893851 | EY5: 0.38626737 | EZ5: 0.31532959 | FA5: 0.034475746 | FB5: 0.16780436 | FC5: 0.019318795 | FD5: -0.026405258 | FE5: -0.032578191 | FF5: 0.048178249 | FG5: 0.17179071 | FH5: -0.26320162 | FI5: -0.36766602 | FJ5: -0.40326734 | FK5: -0.098349831 | FL5: -0.090491811 | FM5: -0.0086173831
B6: 0.22925861 | C6: 0.61157404 | D6: 1.1059457 | E6: 0.91820281 | F6: 1.6606166 | AQ6: 0 | AR6: 0 | AS6: 0 | AT6: 0 | AU6: 1.6606166 | AV6: 0.73215126 | AW6: 0.34680851 | AX6: 0.6069518 | AY6: 1.4997598 | AZ6: 0.65674393 | BA6: 0.4740838 | BB6: 0.65687069 | BC6: 0.3197238 | BD6: 0.34113924 | BE6: 0.41262888 | BF6: 0.37875601 | BG6: 0.82886038 | BH6: 0.61387774 | BI6: 0.66839607 | BJ6: 0.18166238 | BK6: 0.10476645 | BL6: 0.83775942 | BM6: 0.91927999 | BN6: 0.65852657 | BO6: 0.062437226 | BP6: 0.47800348 | BQ6: 0.3513697 | BR6: 0.64220254 | BS6: 0.50200183 | BT6: 0.18484931 | BU6: 0.44544432 | BV6: 0.51569684 | BW6: 0.59817429 | BX6: 0.21228118 | BY6: 0.38229033 | BZ6: 0.24011147 | CA6: 0.7792046 | CB6: 0.38541738 | CC6: 0.015597554 | CJ6: 0.22925861 | CK6: 0.61157404 | CL6: 1.1059457 | CM6: 0.91820281 | CN6: 1.6606166 | CO6: 0.73215126 | CP6: 0.34680851 | CQ6: 0.6069518 | CR6: 1.4997598 | CS6: 0.65674393 | CT6: 0.4740838 | CU6: 0.65687069 | CV6: 0.3197238 | CW6: 0.34113924 | CX6: 0.41262888 | CY6: 0.37875601 | CZ6: 0.82886038 | DA6: 0.61387774 | DB6: 0.66839607 | DC6: 0.18166238 | DD6: 0.10476645 | DE6: 0.83775942 | DF6: 0.91927999 | DG6: 0.65852657 | DH6: 0.062437226 | DI6: 0.47800348 | DJ6: 0.3513697 | DK6: 0.64220254 | DL6: 0.50200183 | DM6: 0.18484931 | DN6: 0.44544432 | DO6: 0.51569684 | DP6: 0.59817429 | DQ6: 0.21228118 | DR6: 0.38229033 | DS6: 0.24011147 | DT6: 0.7792046 | DU6: 0.38541738 | DV6: 0.015597554 | DZ6: 3.4104933 | EA6: -0.016526222 | EB6: -0.016607557 | EC6: -0.1771004 | ED6: -0.093720708 | EE6: -0.19321202 | EF6: -0.07890094 | EG6: -0.16638021 | EH6: -0.088951591 | EI6: -0.19519125 | EJ6: 0.36410613 | EK6: 0.0046690452 | EL6: -0.11809229 | EM6: 0.3628888 | EN6: 0.23139569 | EO6: 0.01565912 | EP6: -0.0072497392 | EQ6: 0.0031445262 | ER6: 0.016642167 | ES6: -0.13169512 | ET6: -0.067212854 | EU6: 0.036556084 | EV6: -0.029888383 | EW6: -0.14657975 | EX6: -0.032798972 | EY6: 0.11000843 | EZ6: 0.037159245 | FA6: 0.0039600271 | FB6: 0.092176901 | FC6: -0.021079407 | FD6: 0.008668346 | FE6: 0.0097107194 | FF6: 0.039855774 | FG6: -0.034918495 | FH6: -0.13052846 | FI6: 0.50082631 | FJ6: -0.34665666 | FK6: 0.2090834 | FL6: -0.0061448125 | FM6: 0.076398439
B7: 0.23435357 | C7: 0.45003988 | D7: 0.9492222 | E7: 0.57603503 | F7: 0.73215126 | G7: 0.94270238 | AQ7: 0 | AR7: 0 | AS7: 0 | AT7: 0 | AU7: 0 | AV7: 0.94270238 | AW7: 0.22896893 | AX7: 0.39104661 | AY7: 0.70221951 | AZ7: 0.51267506 | BA7: 0.35875499 | BB7: 0.50650007 | BC7: 0.34250525 | BD7: 0.27099766 | BE7: 0.261748 | BF7: 0.30782415 | BG7: 0.6423791 | BH7: 0.43313272 | BI7: 0.40214799 | BJ7: 0.10455381 | BK7: 0.1124374 | BL7: 0.56667859 | BM7: 0.37738795 | BN7: 0.34413926 | BO7: 0.42413139 | BP7: 0.44927886 | BQ7: 0.23616967 | BR7: 0.38522588 | BS7: 0.3574028 | BT7: 0.15582966 | BU7: 0.36201872 | BV7: 0.32628516 | BW7: 0.34201211 | BX7: 0.25165004 | BY7: 0.21873489 | BZ7: 0.26566458 | CA7: 0.56111945 | CB7: 0.28356275 | CC7: 0.05966087 | CJ7: 0.23435357 | CK7: 0.45003988 | CL7: 0.9492222 | CM7: 0.57603503 | CN7: 0.73215126 | CO7: 0.94270238 | CP7: 0.22896893 | CQ7: 0.39104661 | CR7: 0.70221951 | CS7: 0.51267506 | CT7: 0.35875499 | CU7: 0.50650007 | CV7: 0.34250525 | CW7: 0.27099766 | CX7: 0.261748 | CY7: 0.30782415 | CZ7: 0.6423791 | DA7: 0.43313272 | DB7: 0.40214799 | DC7: 0.10455381 | DD7: 0.1124374 | DE7: 0.56667859 | DF7: 0.37738795 | DG7: 0.34413926 | DH7: 0.42413139 | DI7: 0.44927886 | DJ7: 0.23616967 | DK7: 0.38522588 | DL7: 0.3574028 | DM7: 0.15582966 | DN7: 0.36201872 | DO7: 0.32628516 | DP7: 0.34201211 | DQ7: 0.25165004 | DR7: 0.21873489 | DS7: 0.26566458 | DT7: 0.56111945 | DU7: 0.28356275 | DV7: 0.05966087 | DZ7: 3.2321673 | EA7: 0.0014691646 | EB7: -0.054709601 | EC7: 0.0054497558 | ED7: -0.087508013 | EE7: -0.28372374 | EF7: -0.032452978 | EG7: 0.020970075 | EH7: -0.055817744 | EI7: -0.22724095 | EJ7: -0.079794401 | EK7: 0.0066081756 | EL7: 0.025574965 | EM7: -0.031972874 | EN7: 0.2023541 | EO7: 0.052099233 | EP7: -0.0065904697 | EQ7: -0.0082763887 | ER7: -0.065611245 | ES7: 0.067152538 | ET7: -0.036532022 | EU7: 0.063808548 | EV7: 0.026763313 | EW7: -0.14807234 | EX7: -0.071100374 | EY7: 0.4944802 | EZ7: 0.21562533 | FA7: -9.8690282e-05 | FB7: -0.065699662 | FC7: 0.017883949 | FD7: 0.011317404 | FE7: 0.043574781 | FF7: -0.2743404 | FG7: 0.02009741 | FH7: 0.28166281 | FI7: 0.12870747 | FJ7: 0.52256973 | FK7: -0.10540419 | FL7: 0.066233444 | FM7: -0.031352317
B8: 0.08156975 | C8: -0.21364916 | D8: 0.39493442 | E8: 0.44761389 | F8: 0.34680851 | G8: 0.22896893 | H8: 1.597426 | AQ8: 0 | AR8: 0 | AS8: 0 | AT8: 0 | AU8: 0 | AV8: 0 | AW8: 1.597426 | AX8: 0.40849158 | AY8: 0.48132082 | AZ8: -0.072897514 | BA8: 0.12105921 | BB8: 0.63540725 | BC8: 0.26142719 | BD8: 0.1884868 | BE8: 0.10505124 | BF8: 0.19222494 | BG8: 0.38739333 | BH8: 0.31371295 | BI8: 0.32769441 | BJ8: 0.1052333 | BK8: 0.13151349 | BL8: 0.36976096 | BM8: 0.23811404 | BN8: 0.18253549 | BO8: 0.28286254 | BP8: 0.35839523 | BQ8: 0.10075386 | BR8: 0.29127638 | BS8: 0.22276374 | BT8: 0.090774139 | BU8: 0.20802044 | BV8: 0.21365829 | BW8: 0.23830321 | BX8: 0.17380109 | BY8: 0.015599052 | BZ8: 0.19514112 | CA8: 0.41281799 | CB8: 0.15218121 | CC8: 0.049081679 | CJ8: 0.08156975 | CK8: -0.21364916 | CL8: 0.39493442 | CM8: 0.44761389 | CN8: 0.34680851 | CO8: 0.22896893 | CP8: 1.597426 | CQ8: 0.40849158 | CR8: 0.48132082 | CS8: -0.072897514 | CT8: 0.12105921 | CU8: 0.63540725 | CV8: 0.26142719 | CW8: 0.1884868 | CX8: 0.10505124 | CY8: 0.19222494 | CZ8: 0.38739333 | DA8: 0.31371295 | DB8: 0.32769441 | DC8: 0.1052333 | DD8: 0.13151349 | DE8: 0.36976096 | DF8: 0.23811404 | DG8: 0.18253549 | DH8: 0.28286254 | DI8: 0.35839523 | DJ8: 0.10075386 | DK8: 0.29127638 | DL8: 0.22276374 | DM8: 0.090774139 | DN8: 0.20802044 | DO8: 0.21365829 | DP8: 0.23830321 | DQ8: 0.17380109 | DR8: 0.015599052 | DS8: 0.19514112 | DT8: 0.41281799 | DU8: 0.15218121 | DV8: 0.049081679 | DZ8: 2.5140368 | EA8: -0.035319937 | EB8: 0.0076592538 | EC8: -0.31602111 | ED8: -0.083399213 | EE8: -0.066073389 | EF8: -0.1145615 | EG8: -0.067882812 | EH8: -0.15804659 | EI8: -0.1041169 | EJ8: -0.044600795 | EK8: -0.091889078 | EL8: -0.12758064 | EM8: -0.11579682 | EN8: 0.15872079 | EO8: 0.1068057 | EP8: 0.043255665 | EQ8: 0.00061711237 | ER8: 0.036924981 | ES8: 0.013729797 | ET8: 0.041435643 | EU8: 0.098642483 | EV8: 0.10111495 | EW8: -0.016159775 | EX8: 0.085240909 | EY8: -0.31677986 | EZ8: 0.19347733 | FA8: -0.016173659 | FB8: 0.36973807 | FC8: -0.043297963 | FD8: -0.059494057 | FE8: -0.066778722 | FF8: 0.56124013 | FG8: 0.079936757 | FH8: 0.075988098 | FI8: -0.026210519 | FJ8: 0.32764323 | FK8: -0.032568785 | FL8: -0.0057438676 | FM8: -0.060842214
B9: 0.22559868 | C9: 0.24784203 | D9: 0.68021466 | E9: 0.86293525 | F9: 0.6069518 | G9: 0.39104661 | H9: 0.40849158 | I9: 1.1652557 | AQ9: 0 | AR9: 0 | AS9: 0 | AT9: 0 | AU9: 0 | AV9: 0 | AW9: 0 | AX9: 1.1652557 | AY9: 0.90378074 | AZ9: 0.44316238 | BA9: 0.57732054 | BB9: 0.48548012 | BC9: 0.24046816 | BD9: 0.12343861 | BE9: 0.15237618 | BF9: 0.26396185 | BG9: 0.59750796 | BH9: 0.44758381 | BI9: 0.4976934 | BJ9: 0.12290312 | BK9: -0.1824347 | BL9: 0.43360889 | BM9: 0.045434917 | BN9: 0.29975694 | BO9: 0.4815302 | BP9: 0.5300651 | BQ9: 0.25475046 | BR9: 0.40393195 | BS9: 0.37964889 | BT9: 0.15812724 | BU9: 0.32298137 | BV9: 0.35892671 | BW9: 0.45168982 | BX9: 0.16837669 | BY9: 0.264336 | BZ9: 0.1618536 | CA9: 0.56501083 | CB9: 0.24126435 | CC9: 0.034589144 | CJ9: 0.22559868 | CK9: 0.24784203 | CL9: 0.68021466 | CM9: 0.86293525 | CN9: 0.6069518 | CO9: 0.39104661 | CP9: 0.40849158 | CQ9: 1.1652557 | CR9: 0.90378074 | CS9: 0.44316238 | CT9: 0.57732054 | CU9: 0.48548012 | CV9: 0.24046816 | CW9: 0.12343861 | CX9: 0.15237618 | CY9: 0.26396185 | CZ9: 0.59750796 | DA9: 0.44758381 | DB9: 0.4976934 | DC9: 0.12290312 | DD9: -0.1824347 | DE9: 0.43360889 | DF9: 0.045434917 | DG9: 0.29975694 | DH9: 0.4815302 | DI9: 0.5300651 | DJ9: 0.25475046 | DK9: 0.40393195 | DL9: 0.37964889 | DM9: 0.15812724 | DN9: 0.32298137 | DO9: 0.35892671 | DP9: 0.45168982 | DQ9: 0.16837669 | DR9: 0.264336 | DS9: 0.1618536 | DT9: 0.56501083 | DU9: 0.24126435 | DV9: 0.034589144 | DZ9: 2.001614 | EA9: -0.024004899 | EB9: -0.26111447 | EC9: -0.17230507 | ED9: 0.2241517 | EE9: -0.11152572 | EF9: -0.02591049 | EG9: 0.61884501 | EH9: 0.34140133 | EI9: -0.046011737 | EJ9: -0.16907758 | EK9: 0.066102059 | EL9: 0.077959531 | EM9: 0.16575598 | EN9: -0.070610964 | EO9: -0.11496706 | EP9: -0.019382877 | EQ9: 0.013053234 | ER9: 0.039886001 | ES9: -0.1552984 | ET9: -0.099843306 | EU9: -0.14169487 | EV9: -0.13694448 | EW9: -0.24815458 | EX9: -0.044398404 | EY9: 0.086522179 | EZ9: 0.067087265 | FA9: -0.019543664 | FB9: 0.22923058 | FC9: 0.0031574237 | FD9: 0.014171845 | FE9: -0.0049425942 | FF9: 0.13648271 | FG9: -0.026154809 | FH9: -0.0034384296 | FI9: -0.065014249 | FJ9: -0.028903419 | FK9: 0.14918308 | FL9: -0.03268971 | FM9: 0.019488543
B10: 0.35352581 | C10: 0.60701966 | D10: 1.1813304 | E10: 0.81851636 | F10: 1.4997598 | G10: 0.70221951 | H10: 0.48132082 | I10: 0.90378074 | J10: 1.9305216 | AQ10: 0 | AR10: 0 | AS10: 0 | AT10: 0 | AU10: 0 | AV10: 0 | AW10: 0 | AX10: 0 | AY10: 1.9305216 | AZ10: 0.82516555 | BA10: 0.67995883 | BB10: 0.88895916 | BC10: 0.4250079 | BD10: 0.37625016 | BE10: 0.46437727 | BF10: 0.47260973 | BG10: 1.0613613 | BH10: 0.80102241 | BI10: 0.94529378 | BJ10: 0.26665283 | BK10: 0.15670271 | BL10: 0.9867346 | BM10: 1.0922759 | BN10: 0.68914961 | BO10: 0.37454517 | BP10: 0.80107377 | BQ10: 0.4401378 | BR10: 0.66188905 | BS10: 0.64935623 | BT10: 0.24153839 | BU10: 0.57564332 | BV10: 0.59255719 | BW10: 0.78977023 | BX10: 0.26715796 | BY10: 0.42835865 | BZ10: 0.32311588 | CA10: 1.0332105 | CB10: 0.47152163 | CC10: 0.032977981 | CJ10: 0.35352581 | CK10: 0.60701966 | CL10: 1.1813304 | CM10: 0.81851636 | CN10: 1.4997598 | CO10: 0.70221951 | CP10: 0.48132082 | CQ10: 0.90378074 | CR10: 1.9305216 | CS10: 0.82516555 | CT10: 0.67995883 | CU10: 0.88895916 | CV10: 0.4250079 | CW10: 0.37625016 | CX10: 0.46437727 | CY10: 0.47260973 | CZ10: 1.0613613 | DA10: 0.80102241 | DB10: 0.94529378 | DC10: 0.26665283 | DD10: 0.15670271 | DE10: 0.9867346 | DF10: 1.0922759 | DG10: 0.68914961 | DH10: 0.37454517 | DI10: 0.80107377 | DJ10: 0.4401378 | DK10: 0.66188905 | DL10: 0.64935623 | DM10: 0.24153839 | DN10: 0.57564332 | DO10: 0.59255719 | DP10: 0.78977023 | DQ10: 0.26715796 | DR10: 0.42835865 | DS10: 0.32311588 | DT10: 1.0332105 | DU10: 0.47152163 | DV10: 0.032977981 | DZ10: 1.8791099 | EA10: -0.093825443 | EB10: -0.33549767 | EC10: -0.42581295 | ED10: -0.12775251 | EE10: 0.14893258 | EF10: -0.1220294 | EG10: 0.27665231 | EH10: -0.085780708 | EI10: 0.24177255 | EJ10: 0.10714106 | EK10: -0.11800732 | EL10: 0.044225948 | EM10: -0.051989548 | EN10: 0.17206658 | EO10: 0.15359879 | EP10: -0.038495531 | EQ10: -0.10035919 | ER10: -0.051927081 | ES10: 0.28399743 | ET10: -0.010554426 | EU10: 0.034240244 | EV10: 0.11264629 | EW10: 0.35307986 | EX10: 0.048542301 | EY10: 0.029936214 | EZ10: 0.005298974 | FA10: -0.054229239 | FB10: 0.1110405 | FC10: -0.031055885 | FD10: -0.00084568444 | FE10: -0.0049276548 | FF10: -0.34200978 | FG10: 0.1321118 | FH10: -0.099105368 | FI10: 0.047825994 | FJ10: -0.094272139 | FK10: -0.085242775 | FL10: 0.049813459 | FM10: -0.0080067659
B11: 0.26921205 | C11: 0.41966795 | D11: 0.82781401 | E11: 0.56275642 | F11: 0.65674393 | G11: 0.51267506 | H11: -0.072897514 | I11: 0.44316238 | J11: 0.82516555 | K11: 4.3799371 | AQ11: 0 | AR11: 0 | AS11: 0 | AT11: 0 | AU11: 0 | AV11: 0 | AW11: 0 | AX11: 0 | AY11: 0 | AZ11: 4.3799371 | BA11: 0.58111361 | BB11: 0.57732068 | BC11: 2.6245007 | BD11: 1.2663945 | BE11: 0.51119209 | BF11: 0.46385929 | BG11: 0.94422141 | BH11: 0.71819911 | BI11: 0.69010063 | BJ11: 0.19894943 | BK11: 0.27462167 | BL11: 0.9109478 | BM11: 0.44374873 | BN11: 0.46235224 | BO11: 0.7609799 | BP11: 0.82114021 | BQ11: 0.39351873 | BR11: 0.60179651 | BS11: 0.50826014 | BT11: 0.27369148 | BU11: 0.57499105 | BV11: 0.56287129 | BW11: 0.62944683 | BX11: 0.44699003 | BY11: -1.9317824 | BZ11: 0.45298989 | CA11: 1.0504408 | CB11: 0.39534727 | CC11: 0.16108059 | CJ11: 0.26921205 | CK11: 0.41966795 | CL11: 0.82781401 | CM11: 0.56275642 | CN11: 0.65674393 | CO11: 0.51267506 | CP11: -0.072897514 | CQ11: 0.44316238 | CR11: 0.82516555 | CS11: 4.3799371 | CT11: 0.58111361 | CU11: 0.57732068 | CV11: 2.6245007 | CW11: 1.2663945 | CX11: 0.51119209 | CY11: 0.46385929 | CZ11: 0.94422141 | DA11: 0.71819911 | DB11: 0.69010063 | DC11: 0.19894943 | DD11: 0.27462167 | DE11: 0.9109478 | DF11: 0.44374873 | DG11: 0.46235224 | DH11: 0.7609799 | DI11: 0.82114021 | DJ11: 0.39351873 | DK11: 0.60179651 | DL11: 0.50826014 | DM11: 0.27369148 | DN11: 0.57499105 | DO11: 0.56287129 | DP11: 0.62944683 | DQ11: 0.44699003 | DR11: -1.9317824 | DS11: 0.45298989 | DT11: 1.0504408 | DU11: 0.39534727 | DV11: 0.16108059 | DZ11: 1.754538 | EA11: 0.0017387437 | EB11: 0.14965606 | EC11: -0.26429868 | ED11: 0.27868976 | EE11: 0.18505263 | EF11: 0.037608854 | EG11: -0.35563339 | EH11: 0.29105739 | EI11: 0.13878595 | EJ11: 0.10612673 | EK11: 0.14690773 | EL11: -0.34307894 | EM11: -0.071826439 | EN11: -0.072136455 | EO11: -0.085396076 | EP11: 0.0005179262 | EQ11: -0.035603216 | ER11: -0.015521932 | ES11: 0.089383678 | ET11: -0.0072217888 | EU11: -0.25695358 | EV11: -0.19076808 | EW11: -0.069343286 | EX11: -0.022502755 | EY11: 0.11845493 | EZ11: -0.11782621 | FA11: 0.035630185 | FB11: 0.38991893 | FC11: -0.052817025 | FD11: -0.016771182 | FE11: -0.036317003 | FF11: -0.2273673 | FG11: 0.022176583 | FH11: 0.079073856 | FI11: 0.04765049 | FJ11: 0.1490771 | FK11: -0.0396352 | FL11: -0.04010242 | FM11: -0.082204304
B12: 0.22315948 | C12: 0.39101128 | D12: 0.67492121 | E12: 0.50464835 | F12: 0.4740838 | G12: 0.35875499 | H12: 0.12105921 | I12: 0.57732054 | J12: 0.67995883 | K12: 0.58111361 | L12: 0.93412032 | AQ12: 0 | AR12: 0 | AS12: 0 | AT12: 0 | AU12: 0 | AV12: 0 | AW12: 0 | AX12: 0 | AY12: 0 | AZ12: 0 | BA12: 0.93412032 | BB12: 0.52069787 | BC12: 0.32024628 | BD12: 0.20176888 | BE12: 0.082595198 | BF12: 0.35506842 | BG12: 0.66452024 | BH12: 0.44422565 | BI12: 0.53090449 | BJ12: 0.20759527 | BK12: 0.1522281 | BL12: 0.47322393 | BM12: 0.21717602 | BN12: 0.3054568 | BO12: 0.57155079 | BP12: 0.5731374 | BQ12: 0.30371274 | BR12: 0.39433419 | BS12: 0.35935314 | BT12: 0.14509472 | BU12: 0.33575247 | BV12: 0.37999551 | BW12: 0.4501929 | BX12: 0.19098008 | BY12: 0.33251181 | BZ12: 0.16972962 | CA12: 0.59898701 | CB12: 0.24522094 | CC12: 0.015766142 | CJ12: 0.22315948 | CK12: 0.39101128 | CL12: 0.67492121 | CM12: 0.50464835 | CN12: 0.4740838 | CO12: 0.35875499 | CP12: 0.12105921 | CQ12: 0.57732054 | CR12: 0.67995883 | CS12: 0.58111361 | CT12: 0.93412032 | CU12: 0.52069787 | CV12: 0.32024628 | CW12: 0.20176888 | CX12: 0.082595198 | CY12: 0.35506842 | CZ12: 0.66452024 | DA12: 0.44422565 | DB12: 0.53090449 | DC12: 0.20759527 | DD12: 0.1522281 | DE12: 0.47322393 | DF12: 0.21717602 | DG12: 0.3054568 | DH12: 0.57155079 | DI12: 0.5731374 | DJ12: 0.30371274 | DK12: 0.39433419 | DL12: 0.35935314 | DM12: 0.14509472 | DN12: 0.33575247 | DO12: 0.37999551 | DP12: 0.4501929 | DQ12: 0.19098008 | DR12: 0.33251181 | DS12: 0.16972962 | DT12: 0.59898701 | DU12: 0.24522094 | DV12: 0.015766142 | DZ12: 1.4822656 | EA12: -0.039480587 | EB12: -0.30965766 | EC12: 0.041562892 | ED12: 0.029365502 | EE12: -0.11271259 | EF12: -0.13683698 | EG12: -0.13133696 | EH12: 0.23691507 | EI12: 0.033057781 | EJ12: 0.23630249 | EK12: 0.096653474 | EL12: -0.039548062 | EM12: -0.13165698 | EN12: -0.0051731988 | EO12: -0.045021491 | EP12: -0.088547228 | EQ12: -0.044011099 | ER12: 0.030762082 | ES12: 0.28111869 | ET12: -0.089328825 | EU12: -0.28195229 | EV12: -0.22081922 | EW12: -0.063994097 | EX12: -0.061764127 | EY12: -0.18540741 | EZ12: 0.23919617 | FA12: -0.005394095 | FB12: -0.4455112 | FC12: 0.10618701 | FD12: 0.051155015 | FE12: -0.024492729 | FF12: 0.20652888 | FG12: 0.33581819 | FH12: 0.015198432 | FI12: 0.084096262 | FJ12: 0.02794094 | FK12: -0.066755383 | FL12: 0.038339387 | FM12: 0.0014165006
B13: 0.23538403 | C13: 0.49117256 | D13: 1.0775111 | E13: 0.58141 | F13: 0.65687069 | G13: 0.50650007 | H13: 0.63540725 | I13: 0.48548012 | J13: 0.88895916 | K13: 0.57732068 | L13: 0.52069787 | M13: 1.4546117 | AQ13: 0 | AR13: 0 | AS13: 0 | AT13: 0 | AU13: 0 | AV13: 0 | AW13: 0 | AX13: 0 | AY13: 0 | AZ13: 0 | BA13: 0 | BB13: 1.4546117 | BC13: 0.42301649 | BD13: 0.4465371 | BE13: 0.4064764 | BF13: 0.50309887 | BG13: 0.94357918 | BH13: 0.70315858 | BI13: 0.78245962 | BJ13: 0.27896532 | BK13: 0.17565563 | BL13: 0.98136839 | BM13: 0.5238764 | BN13: 0.47012117 | BO13: 0.65220809 | BP13: 0.72867353 | BQ13: 0.22483677 | BR13: 0.26494318 | BS13: 0.48704365 | BT13: 0.1663525 | BU13: 0.4794539 | BV13: 0.47927398 | BW13: 0.58297403 | BX13: 0.23713267 | BY13: 0.22040583 | BZ13: 0.31047671 | CA13: 0.82337477 | CB13: 0.39804526 | CC13: 0.072262665 | CJ13: 0.23538403 | CK13: 0.49117256 | CL13: 1.0775111 | CM13: 0.58141 | CN13: 0.65687069 | CO13: 0.50650007 | CP13: 0.63540725 | CQ13: 0.48548012 | CR13: 0.88895916 | CS13: 0.57732068 | CT13: 0.52069787 | CU13: 1.4546117 | CV13: 0.42301649 | CW13: 0.4465371 | CX13: 0.4064764 | CY13: 0.50309887 | CZ13: 0.94357918 | DA13: 0.70315858 | DB13: 0.78245962 | DC13: 0.27896532 | DD13: 0.17565563 | DE13: 0.98136839 | DF13: 0.5238764 | DG13: 0.47012117 | DH13: 0.65220809 | DI13: 0.72867353 | DJ13: 0.22483677 | DK13: 0.26494318 | DL13: 0.48704365 | DM13: 0.1663525 | DN13: 0.4794539 | DO13: 0.47927398 | DP13: 0.58297403 | DQ13: 0.23713267 | DR13: 0.22040583 | DS13: 0.31047671 | DT13: 0.82337477 | DU13: 0.39804526 | DV13: 0.072262665 | DZ13: 1.3180243 | EA13: 0.0023345352 | EB13: -0.066752356 | EC13: -0.15392239 | ED13: -0.24311275 | EE13: -0.025948591 | EF13: -0.039078558 | EG13: -0.12936219 | EH13: -0.11280134 | EI13: 0.10040375 | EJ13: -0.092053048 | EK13: -0.011342894 | EL13: -0.10034502 | EM13: 0.0083617226 | EN13: -0.30721128 | EO13: -0.024429704 | EP13: -0.14990282 | EQ13: 0.23303526 | ER13: 0.061093543 | ES13: -0.16221842 | ET13: -0.38392583 | EU13: 0.072326133 | EV13: -0.094388463 | EW13: 0.11737056 | EX13: -0.051917465 | EY13: 0.054632738 | EZ13: -0.032781874 | FA13: 0.037968049 | FB13: 0.0057353478 | FC13: 0.36044764 | FD13: 0.096842542 | FE13: 0.18884216 | FF13: -0.038332155 | FG13: 0.10217207 | FH13: -0.15016568 | FI13: -0.091435325 | FJ13: 0.17374697 | FK13: 0.40150918 | FL13: 0.17083095 | FM13: -0.16898474
B14: 0.14482896 | C14: 0.18400557 | D14: 0.4473199 | E14: 0.28381878 | F14: 0.3197238 | G14: 0.34250525 | H14: 0.26142719 | I14: 0.24046816 | J14: 0.4250079 | K14: 2.6245007 | L14: 0.32024628 | M14: 0.42301649 | N14: 2.7903653 | AQ14: 0 | AR14: 0 | AS14: 0 | AT14: 0 | AU14: 0 | AV14: 0 | AW14: 0 | AX14: 0 | AY14: 0 | AZ14: 0 | BA14: 0 | BB14: 0 | BC14: 2.7903653 | BD14: 1.1164676 | BE14: 0.015278243 | BF14: 0.31761444 | BG14: 0.61126763 | BH14: 0.42483143 | BI14: -0.14833051 | BJ14: -0.0063907429 | BK14: 0.063348462 | BL14: 0.39805486 | BM14: 0.23734662 | BN14: 0.25194945 | BO14: 0.32339577 | BP14: 0.1405793 | BQ14: 0.20858217 | BR14: 0.22900201 | BS14: 0.19051929 | BT14: 0.17974495 | BU14: 0.35103584 | BV14: 0.23932443 | BW14: 0.12022357 | BX14: 0.51892834 | BY14: -1.2211636 | BZ14: 0.46713702 | CA14: 0.93300613 | CB14: 0.22285397 | CC14: 0.15364916 | CJ14: 0.14482896 | CK14: 0.18400557 | CL14: 0.4473199 | CM14: 0.28381878 | CN14: 0.3197238 | CO14: 0.34250525 | CP14: 0.26142719 | CQ14: 0.24046816 | CR14: 0.4250079 | CS14: 2.6245007 | CT14: 0.32024628 | CU14: 0.42301649 | CV14: 2.7903653 | CW14: 1.1164676 | CX14: 0.015278243 | CY14: 0.31761444 | CZ14: 0.61126763 | DA14: 0.42483143 | DB14: -0.14833051 | DC14: -0.0063907429 | DD14: 0.063348462 | DE14: 0.39805486 | DF14: 0.23734662 | DG14: 0.25194945 | DH14: 0.32339577 | DI14: 0.1405793 | DJ14: 0.20858217 | DK14: 0.22900201 | DL14: 0.19051929 | DM14: 0.17974495 | DN14: 0.35103584 | DO14: 0.23932443 | DP14: 0.12022357 | DQ14: 0.51892834 | DR14: -1.2211636 | DS14: 0.46713702 | DT14: 0.93300613 | DU14: 0.22285397 | DV14: 0.15364916 | DZ14: 1.1333525 | EA14: 0.02297867 | EB14: 0.10017522 | EC14: 0.036868514 | ED14: -0.12354876 | EE14: 0.038170248 | EF14: 0.029794199 | EG14: 0.062925205 | EH14: -0.072807293 | EI14: 0.039739352 | EJ14: -0.078519738 | EK14: 0.096303831 | EL14: -0.04061994 | EM14: 0.10590226 | EN14: -0.00948852 | EO14: -0.35293842 | EP14: 0.15528472 | EQ14: 0.014383944 | ER14: 0.019053082 | ES14: 0.16006745 | ET14: -0.47093278 | EU14: 0.30623221 | EV14: -0.042071306 | EW14: -0.033808033 | EX14: -0.026634147 | EY14: -0.067562901 | EZ14: -0.08843873 | FA14: 0.035810774 | FB14: 0.071659448 | FC14: -0.18427309 | FD14: -0.041090182 | FE14: 0.0022175507 | FF14: -0.028059252 | FG14: 0.41836582 | FH14: 0.29850693 | FI14: 0.017139657 | FJ14: -0.099956017 | FK14: -0.096774872 | FL14: -0.25837236 | FM14: 0.17720459
B15: 0.088960172 | C15: 0.20169018 | D15: 0.33282697 | E15: 0.27118553 | F15: 0.34113924 | G15: 0.27099766 | H15: 0.1884868 | I15: 0.12343861 | J15: 0.37625016 | K15: 1.2663945 | L15: 0.20176888 | M15: 0.4465371 | N15: 1.1164676 | O15: 1.6226755 | AQ15: 0 | AR15: 0 | AS15: 0 | AT15: 0 | AU15: 0 | AV15: 0 | AW15: 0 | AX15: 0 | AY15: 0 | AZ15: 0 | BA15: 0 | BB15: 0 | BC15: 0 | BD15: 1.6226755 | BE15: 0.23454188 | BF15: 0.4977419 | BG15: 0.64710788 | BH15: 0.41228094 | BI15: 0.44413565 | BJ15: 0.23216267 | BK15: 0.1424753 | BL15: 0.58452156 | BM15: 0.2858143 | BN15: 0.31818955 | BO15: 0.36552554 | BP15: 0.47623599 | BQ15: 0.14755491 | BR15: 0.29658996 | BS15: 0.2363335 | BT15: 0.099499283 | BU15: 0.31666361 | BV15: 0.29901277 | BW15: 0.29938083 | BX15: 0.4495406 | BY15: 0.25517809 | BZ15: 0.75223637 | CA15: 0.56870238 | CB15: 0.35051499 | CC15: 0.12898099 | CJ15: 0.088960172 | CK15: 0.20169018 | CL15: 0.33282697 | CM15: 0.27118553 | CN15: 0.34113924 | CO15: 0.27099766 | CP15: 0.1884868 | CQ15: 0.12343861 | CR15: 0.37625016 | CS15: 1.2663945 | CT15: 0.20176888 | CU15: 0.4465371 | CV15: 1.1164676 | CW15: 1.6226755 | CX15: 0.23454188 | CY15: 0.4977419 | CZ15: 0.64710788 | DA15: 0.41228094 | DB15: 0.44413565 | DC15: 0.23216267 | DD15: 0.1424753 | DE15: 0.58452156 | DF15: 0.2858143 | DG15: 0.31818955 | DH15: 0.36552554 | DI15: 0.47623599 | DJ15: 0.14755491 | DK15: 0.29658996 | DL15: 0.2363335 | DM15: 0.099499283 | DN15: 0.31666361 | DO15: 0.29901277 | DP15: 0.29938083 | DQ15: 0.4495406 | DR15: 0.25517809 | DS15: 0.75223637 | DT15: 0.56870238 | DU15: 0.35051499 | DV15: 0.12898099 | DZ15: 1.07191 | EA15: 0.061858015 | EB15: -0.19032792 | EC15: 0.075133314 | ED15: -0.22225555 | EE15: 0.071597313 | EF15: 0.04789385 | EG15: 0.032106379 | EH15: 0.046240406 | EI15: 0.25022994 | EJ15: 0.13015109 | EK15: 0.2358479 | EL15: -0.20547906 | EM15: -0.032054862 | EN15: -0.22093622 | EO15: -0.21169908 | EP15: -0.060399007 | EQ15: -0.12610827 | ER15: -0.07565013 | ES15: -0.15974858 | ET15: 0.25803463 | EU15: 0.35677622 | EV15: -0.15039546 | EW15: 0.12009845 | EX15: -0.12003837 | EY15: -0.0017861347 | EZ15: 0.45830822 | FA15: 0.091397755 | FB15: 0.072319027 | FC15: -0.070688746 | FD15: 0.089026024 | FE15: -0.002333962 | FF15: 0.0067738474 | FG15: -0.25943867 | FH15: 0.11022014 | FI15: 0.068095932 | FJ15: -0.0036959795 | FK15: -0.035836149 | FL15: -0.036426473 | FM15: 0.05308314
B16: 0.173228 | C16: 0.43393911 | D16: 0.58713485 | E16: 0.38984386 | F16: 0.41262888 | G16: 0.261748 | H16: 0.10505124 | I16: 0.15237618 | J16: 0.46437727 | K16: 0.51119209 | L16: 0.082595198 | M16: 0.4064764 | N16: 0.015278243 | O16: 0.23454188 | P16: 1.8000471 | AQ16: 0 | AR16: 0 | AS16: 0 | AT16: 0 | AU16: 0 | AV16: 0 | AW16: 0 | AX16: 0 | AY16: 0 | AZ16: 0 | BA16: 0 | BB16: 0 | BC16: 0 | BD16: 0 | BE16: 1.8000471 | BF16: -0.81963867 | BG16: -0.56939881 | BH16: -0.65583481 | BI16: -0.42192286 | BJ16: -0.93852698 | BK16: -0.043810649 | BL16: 0.69435733 | BM16: 0.36694941 | BN16: 0.35443177 | BO16: 0.48729617 | BP16: 0.69588809 | BQ16: 0.21309189 | BR16: 0.51572476 | BS16: 0.30265129 | BT16: 0.046942408 | BU16: 0.22997119 | BV16: 0.54265559 | BW16: 0.45664617 | BX16: 0.041934797 | BY16: 0.28540625 | BZ16: 0.034816823 | CA16: -0.37646459 | CB16: 0.21509375 | CC16: 0.0034232193 | CJ16: 0.173228 | CK16: 0.43393911 | CL16: 0.58713485 | CM16: 0.38984386 | CN16: 0.41262888 | CO16: 0.261748 | CP16: 0.10505124 | CQ16: 0.15237618 | CR16: 0.46437727 | CS16: 0.51119209 | CT16: 0.082595198 | CU16: 0.4064764 | CV16: 0.015278243 | CW16: 0.23454188 | CX16: 1.8000471 | CY16: -0.81963867 | CZ16: -0.56939881 | DA16: -0.65583481 | DB16: -0.42192286 | DC16: -0.93852698 | DD16: -0.043810649 | DE16: 0.69435733 | DF16: 0.36694941 | DG16: 0.35443177 | DH16: 0.48729617 | DI16: 0.69588809 | DJ16: 0.21309189 | DK16: 0.51572476 | DL16: 0.30265129 | DM16: 0.046942408 | DN16: 0.22997119 | DO16: 0.54265559 | DP16: 0.45664617 | DQ16: 0.041934797 | DR16: 0.28540625 | DS16: 0.034816823 | DT16: -0.37646459 | DU16: 0.21509375 | DV16: 0.0034232193 | DZ16: 1.0182966 | EA16: -0.0039759778 | EB16: 0.1537091 | EC16: 0.16123438 | ED16: 0.022406209 | EE16: 0.028643023 | EF16: 0.0052013463 | EG16: 0.020721524 | EH16: -0.15258969 | EI16: 0.011830675 | EJ16: -0.13185833 | EK16: -0.16628177 | EL16: -0.039854975 | EM16: 0.12974438 | EN16: 0.012223063 | EO16: -0.04392553 | EP16: -0.054458071 | EQ16: -0.33767929 | ER16: 0.11690156 | ES16: 0.084301716 | ET16: -0.056733471 | EU16: -0.18857532 | EV16: -0.20555517 | EW16: 0.20802754 | EX16: -0.1295584 | EY16: 0.047428158 | EZ16: 0.21206423 | FA16: -0.0055238272 | FB16: 0.0058810764 | FC16: -0.43375833 | FD16: -0.10979161 | FE16: -0.23584112 | FF16: -0.021353174 | FG16: 0.092877177 | FH16: -0.16521004 | FI16: -0.046369203 | FJ16: 0.13732298 | FK16: 0.4107024 | FL16: 0.19932703 | FM16: 0.1089199
B17: 0.15150791 | C17: 0.20717132 | D17: 0.52058989 | E17: 0.27857859 | F17: 0.37875601 | G17: 0.30782415 | H17: 0.19222494 | I17: 0.26396185 | J17: 0.47260973 | K17: 0.46385929 | L17: 0.35506842 | M17: 0.50309887 | N17: 0.31761444 | O17: 0.4977419 | P17: -0.81963867 | Q17: 2.0077162 | AQ17: 0 | AR17: 0 | AS17: 0 | AT17: 0 | AU17: 0 | AV17: 0 | AW17: 0 | AX17: 0 | AY17: 0 | AZ17: 0 | BA17: 0 | BB17: 0 | BC17: 0 | BD17: 0 | BE17: 0 | BF17: 2.0077162 | BG17: 2.1158157 | BH17: 1.7656856 | BI17: 1.7402565 | BJ17: 1.6078109 | BK17: 0.24989279 | BL17: 0.63760392 | BM17: 0.25764321 | BN17: 0.29763639 | BO17: 0.47815766 | BP17: 0.39622013 | BQ17: 0.24605356 | BR17: 0.43994914 | BS17: 0.16703232 | BT17: 0.13478342 | BU17: 0.4170675 | BV17: 0.27287558 | BW17: 0.36869263 | BX17: 0.19594429 | BY17: 0.18227706 | BZ17: 0.28257735 | CA17: 1.488334 | CB17: 0.29318111 | CC17: 0.045674401 | CJ17: 0.15150791 | CK17: 0.20717132 | CL17: 0.52058989 | CM17: 0.27857859 | CN17: 0.37875601 | CO17: 0.30782415 | CP17: 0.19222494 | CQ17: 0.26396185 | CR17: 0.47260973 | CS17: 0.46385929 | CT17: 0.35506842 | CU17: 0.50309887 | CV17: 0.31761444 | CW17: 0.4977419 | CX17: -0.81963867 | CY17: 2.0077162 | CZ17: 2.1158157 | DA17: 1.7656856 | DB17: 1.7402565 | DC17: 1.6078109 | DD17: 0.24989279 | DE17: 0.63760392 | DF17: 0.25764321 | DG17: 0.29763639 | DH17: 0.47815766 | DI17: 0.39622013 | DJ17: 0.24605356 | DK17: 0.43994914 | DL17: 0.16703232 | DM17: 0.13478342 | DN17: 0.4170675 | DO17: 0.27287558 | DP17: 0.36869263 | DQ17: 0.19594429 | DR17: 0.18227706 | DS17: 0.28257735 | DT17: 1.488334 | DU17: 0.29318111 | DV17: 0.045674401 | DZ17: 0.85248707 | EA17: -0.0062067025 | EB17: 0.14406116 | EC17: -0.18277751 | ED17: -0.028906517 | EE17: -0.049711665 | EF17: -0.13177544 | EG17: -0.12490957 | EH17: 0.22996909 | EI17: 0.092515251 | EJ17: -0.034871412 | EK17: 0.36312071 | EL17: 0.30380725 | EM17: -0.054754086 | EN17: 0.13133031 | EO17: -0.25402268 | EP17: 0.04557686 | EQ17: -0.1490898 | ER17: -0.16335818 | ES17: -0.018302426 | ET17: -0.029061409 | EU17: 0.25688461 | EV17: 0.18363574 | EW17: -0.21446875 | EX17: 0.13832461 | EY17: -0.091244745 | EZ17: -0.016516135 | FA17: -0.086664764 | FB17: -0.084665942 | FC17: -0.15202803 | FD17: 0.0054611389 | FE17: -0.010106934 | FF17: -0.064241484 | FG17: 0.026168066 | FH17: -0.34066287 | FI17: -0.04783678 | FJ17: 0.099588185 | FK17: 0.053343297 | FL17: 0.37111323 | FM17: -0.027609582
B18: 0.32035219 | C18: 0.58509222 | D18: 1.1318878 | E18: 0.69432571 | F18: 0.82886038 | G18: 0.6423791 | H18: 0.38739333 | I18: 0.59750796 | J18: 1.0613613 | K18: 0.94422141 | L18: 0.66452024 | M18: 0.94357918 | N18: 0.61126763 | O18: 0.64710788 | P18: -0.56939881 | Q18: 2.1158157 | R18: 3.1098014 | AQ18: 0 | AR18: 0 | AS18: 0 | AT18: 0 | AU18: 0 | AV18: 0 | AW18: 0 | AX18: 0 | AY18: 0 | AZ18: 0 | BA18: 0 | BB18: 0 | BC18: 0 | BD18: 0 | BE18: 0 | BF18: 0 | BG18: 3.1098014 | BH18: 2.3728409 | BI18: 2.2548591 | BJ18: 1.759146 | BK18: 0.37196598 | BL18: 1.196812 | BM18: 0.55396548 | BN18: 0.61945008 | BO18: 1.0442267 | BP18: 0.97551602 | BQ18: 0.4851903 | BR18: 0.77302312 | BS18: 1.0486665 | BT18: 0.25909946 | BU18: 0.86158911 | BV18: 0.69942474 | BW18: 0.81836497 | BX18: 0.29314427 | BY18: 0.48072705 | BZ18: 0.42695491 | CA18: 2.2559856 | CB18: 0.53535534 | CC18: -0.016875656 | CJ18: 0.32035219 | CK18: 0.58509222 | CL18: 1.1318878 | CM18: 0.69432571 | CN18: 0.82886038 | CO18: 0.6423791 | CP18: 0.38739333 | CQ18: 0.59750796 | CR18: 1.0613613 | CS18: 0.94422141 | CT18: 0.66452024 | CU18: 0.94357918 | CV18: 0.61126763 | CW18: 0.64710788 | CX18: -0.56939881 | CY18: 2.1158157 | CZ18: 3.1098014 | DA18: 2.3728409 | DB18: 2.2548591 | DC18: 1.759146 | DD18: 0.37196598 | DE18: 1.196812 | DF18: 0.55396548 | DG18: 0.61945008 | DH18: 1.0442267 | DI18: 0.97551602 | DJ18: 0.4851903 | DK18: 0.77302312 | DL18: 1.0486665 | DM18: 0.25909946 | DN18: 0.86158911 | DO18: 0.69942474 | DP18: 0.81836497 | DQ18: 0.29314427 | DR18: 0.48072705 | DS18: 0.42695491 | DT18: 2.2559856 | DU18: 0.53535534 | DV18: -0.016875656 | DZ18: 0.84046821 | EA18: 0.11064908 | EB18: -0.20274946 | EC18: 0.080837684 | ED18: -0.18482276 | EE18: -0.10647181 | EF18: -0.002773387 | EG18: 0.010855631 | EH18: 0.081389721 | EI18: 0.001603181 | EJ18: 0.23960441 | EK18: 0.10804376 | EL18: 0.10831287 | EM18: -0.15023822 | EN18: -0.38811282 | EO18: 0.31210099 | EP18: -0.090226095 | EQ18: -0.21081508 | ER18: 0.14778428 | ES18: 0.1436203 | ET18: 0.049227563 | EU18: 0.11787495 | EV18: 0.12489171 | EW18: -0.15534709 | EX18: -0.018966211 | EY18: 0.075027496 | EZ18: -0.45704279 | FA18: 0.043680792 | FB18: 0.10975519 | FC18: -0.21429163 | FD18: -0.005939884 | FE18: -0.088582962 | FF18: 0.10680786 | FG18: 0.012798032 | FH18: 0.13749413 | FI18: 0.090572422 | FJ18: 0.1163097 | FK18: 0.18702252 | FL18: 0.026436143 | FM18: 0.12175226
B19: 0.22512874 | C19: 0.42200266 | D19: 0.78523229 | E19: 0.50160527 | F19: 0.61387774 | G19: 0.43313272 | H19: 0.31371295 | I19: 0.44758381 | J19: 0.80102241 | K19: 0.71819911 | L19: 0.44422565 | M19: 0.70315858 | N19: 0.42483143 | O19: 0.41228094 | P19: -0.65583481 | Q19: 1.7656856 | R19: 2.3728409 | S19: 2.4212701 | AQ19: 0 | AR19: 0 | AS19: 0 | AT19: 0 | AU19: 0 | AV19: 0 | AW19: 0 | AX19: 0 | AY19: 0 | AZ19: 0 | BA19: 0 | BB19: 0 | BC19: 0 | BD19: 0 | BE19: 0 | BF19: 0 | BG19: 0 | BH19: 2.4212701 | BI19: 2.1731251 | BJ19: 1.74339 | BK19: 0.27333074 | BL19: 0.87631331 | BM19: 0.40046102 | BN19: 0.46851242 | BO19: 0.84423473 | BP19: 0.74497147 | BQ19: 0.36100883 | BR19: 0.61531993 | BS19: 0.57589664 | BT19: 0.22308655 | BU19: 0.44255578 | BV19: 0.65875448 | BW19: 0.65732888 | BX19: 0.14054324 | BY19: 0.33981349 | BZ19: 0.21581677 | CA19: 2.0930477 | CB19: 0.3567293 | CC19: 0.065397757 | CJ19: 0.22512874 | CK19: 0.42200266 | CL19: 0.78523229 | CM19: 0.50160527 | CN19: 0.61387774 | CO19: 0.43313272 | CP19: 0.31371295 | CQ19: 0.44758381 | CR19: 0.80102241 | CS19: 0.71819911 | CT19: 0.44422565 | CU19: 0.70315858 | CV19: 0.42483143 | CW19: 0.41228094 | CX19: -0.65583481 | CY19: 1.7656856 | CZ19: 2.3728409 | DA19: 2.4212701 | DB19: 2.1731251 | DC19: 1.74339 | DD19: 0.27333074 | DE19: 0.87631331 | DF19: 0.40046102 | DG19: 0.46851242 | DH19: 0.84423473 | DI19: 0.74497147 | DJ19: 0.36100883 | DK19: 0.61531993 | DL19: 0.57589664 | DM19: 0.22308655 | DN19: 0.44255578 | DO19: 0.65875448 | DP19: 0.65732888 | DQ19: 0.14054324 | DR19: 0.33981349 | DS19: 0.21581677 | DT19: 2.0930477 | DU19: 0.3567293 | DV19: 0.065397757 | DZ19: 0.81617151 | EA19: 0.064995656 | EB19: -0.28525877 | EC19: 0.1649647 | ED19: -0.040863698 | EE19: 0.014526255 | EF19: 0.22030806 | EG19: -0.047362049 | EH19: -0.0041551233 | EI19: -0.11251885 | EJ19: 0.049457799 | EK19: -0.07481112 | EL19: -0.11297681 | EM19: -0.20372704 | EN19: 0.064715451 | EO19: 0.098857452 | EP19: 0.39696085 | EQ19: 0.17450035 | ER19: -0.10846727 | ES19: -0.089132623 | ET19: -0.17604391 | EU19: -0.085680059 | EV19: -0.068439443 | EW19: -0.050818524 | EX19: -0.12347157 | EY19: -0.069204617 | EZ19: 0.027856423 | FA19: 0.056409083 | FB19: 0.19197223 | FC19: -0.2176781 | FD19: 0.017280188 | FE19: 0.26713879 | FF19: -0.035077625 | FG19: -0.0070903261 | FH19: -0.053697631 | FI19: -0.073239312 | FJ19: -0.10840049 | FK19: -0.13305417 | FL19: 0.49129468 | FM19: 0.17888272
B20: 0.22869586 | C20: 0.52934194 | D20: 0.81560533 | E20: 0.60497673 | F20: 0.66839607 | G20: 0.40214799 | H20: 0.32769441 | I20: 0.4976934 | J20: 0.94529378 | K20: 0.69010063 | L20: 0.53090449 | M20: 0.78245962 | N20: -0.14833051 | O20: 0.44413565 | P20: -0.42192286 | Q20: 1.7402565 | R20: 2.2548591 | S20: 2.1731251 | T20: 3.0804131 | AQ20: 0 | AR20: 0 | AS20: 0 | AT20: 0 | AU20: 0 | AV20: 0 | AW20: 0 | AX20: 0 | AY20: 0 | AZ20: 0 | BA20: 0 | BB20: 0 | BC20: 0 | BD20: 0 | BE20: 0 | BF20: 0 | BG20: 0 | BH20: 0 | BI20: 3.0804131 | BJ20: 1.8103222 | BK20: 0.3461038 | BL20: 1.1111551 | BM20: 0.57111171 | BN20: 0.51546956 | BO20: 1.2357146 | BP20: 1.1315336 | BQ20: 0.4095593 | BR20: 0.64196261 | BS20: 0.60555196 | BT20: 0.18339242 | BU20: 0.50895592 | BV20: 0.39346514 | BW20: 1.2120483 | BX20: 0.11167561 | BY20: 0.29619345 | BZ20: 0.21872841 | CA20: 1.7228905 | CB20: 0.4053989 | CC20: 0.017909816 | CJ20: 0.22869586 | CK20: 0.52934194 | CL20: 0.81560533 | CM20: 0.60497673 | CN20: 0.66839607 | CO20: 0.40214799 | CP20: 0.32769441 | CQ20: 0.4976934 | CR20: 0.94529378 | CS20: 0.69010063 | CT20: 0.53090449 | CU20: 0.78245962 | CV20: -0.14833051 | CW20: 0.44413565 | CX20: -0.42192286 | CY20: 1.7402565 | CZ20: 2.2548591 | DA20: 2.1731251 | DB20: 3.0804131 | DC20: 1.8103222 | DD20: 0.3461038 | DE20: 1.1111551 | DF20: 0.57111171 | DG20: 0.51546956 | DH20: 1.2357146 | DI20: 1.1315336 | DJ20: 0.4095593 | DK20: 0.64196261 | DL20: 0.60555196 | DM20: 0.18339242 | DN20: 0.50895592 | DO20: 0.39346514 | DP20: 1.2120483 | DQ20: 0.11167561 | DR20: 0.29619345 | DS20: 0.21872841 | DT20: 1.7228905 | DU20: 0.4053989 | DV20: 0.017909816 | DZ20: 0.7271107 | EA20: 0.046602838 | EB20: 0.096852186 | EC20: -0.22156359 | ED20: -0.21647567 | EE20: -0.19014791 | EF20: -0.1748992 | EG20: -0.23956611 | EH20: 0.052420175 | EI20: 0.18133584 | EJ20: -0.22786492 | EK20: 0.20797806 | EL20: 0.38121751 | EM20: 0.12112516 | EN20: -0.031459157 | EO20: 0.17095961 | EP20: 0.099233742 | EQ20: 0.062405051 | ER20: 0.025291966 | ES20: -0.11173561 | ET20: 0.049801651 | EU20: -0.32262823 | EV20: -0.10109941 | EW20: 0.20487718 | EX20: -0.026756142 | EY20: 0.052996094 | EZ20: 0.086546707 | FA20: 0.01357348 | FB20: 0.0486056 | FC20: -0.065066697 | FD20: 0.068475094 | FE20: 0.1043206 | FF20: 0.053446776 | FG20: -0.055323885 | FH20: 0.30281367 | FI20: -0.09411396 | FJ20: -0.15648176 | FK20: -0.024922023 | FL20: -0.021567144 | FM20: 0.31031166
B21: 0.06888546 | C21: 0.086711415 | D21: 0.21319549 | E21: 0.10542846 | F21: 0.18166238 | G21: 0.10455381 | H21: 0.1052333 | I21: 0.12290312 | J21: 0.26665283 | K21: 0.19894943 | L21: 0.20759527 | M21: 0.27896532 | N21: -0.0063907429 | O21: 0.23216267 | P21: -0.93852698 | Q21: 1.6078109 | R21: 1.759146 | S21: 1.74339 | T21: 1.8103222 | U21: 2.5748021 | AQ21: 0 | AR21: 0 | AS21: 0 | AT21: 0 | AU21: 0 | AV21: 0 | AW21: 0 | AX21: 0 | AY21: 0 | AZ21: 0 | BA21: 0 | BB21: 0 | BC21: 0 | BD21: 0 | BE21: 0 | BF21: 0 | BG21: 0 | BH21: 0 | BI21: 0 | BJ21: 2.5748021 | BK21: 0.19667525 | BL21: 0.41057693 | BM21: 0.17753907 | BN21: 0.18496357 | BO21: 0.3454446 | BP21: 0.23549243 | BQ21: 0.1194402 | BR21: 0.16204702 | BS21: 0.19296891 | BT21: 0.083381101 | BU21: 0.16310851 | BV21: 0.1328342 | BW21: -0.11629737 | BX21: 0.030396804 | BY21: 0.021147458 | BZ21: 0.16089313 | CA21: 1.3111156 | CB21: 0.16423568 | CC21: -0.0041917052 | CJ21: 0.06888546 | CK21: 0.086711415 | CL21: 0.21319549 | CM21: 0.10542846 | CN21: 0.18166238 | CO21: 0.10455381 | CP21: 0.1052333 | CQ21: 0.12290312 | CR21: 0.26665283 | CS21: 0.19894943 | CT21: 0.20759527 | CU21: 0.27896532 | CV21: -0.0063907429 | CW21: 0.23216267 | CX21: -0.93852698 | CY21: 1.6078109 | CZ21: 1.759146 | DA21: 1.74339 | DB21: 1.8103222 | DC21: 2.5748021 | DD21: 0.19667525 | DE21: 0.41057693 | DF21: 0.17753907 | DG21: 0.18496357 | DH21: 0.3454446 | DI21: 0.23549243 | DJ21: 0.1194402 | DK21: 0.16204702 | DL21: 0.19296891 | DM21: 0.083381101 | DN21: 0.16310851 | DO21: 0.1328342 | DP21: -0.11629737 | DQ21: 0.030396804 | DR21: 0.021147458 | DS21: 0.16089313 | DT21: 1.3111156 | DU21: 0.16423568 | DV21: -0.0041917052 | DZ21: 0.67464642 | EA21: -0.014059851 | EB21: 0.22477536 | EC21: -0.16272452 | ED21: 0.061262377 | EE21: 0.087208896 | EF21: 0.084867813 | EG21: 0.088283897 | EH21: 0.023722556 | EI21: -0.010590206 | EJ21: -0.036769235 | EK21: -0.18979262 | EL21: -0.17796537 | EM21: -0.12160057 | EN21: 0.13134014 | EO21: -0.0099890585 | EP21: -0.28033788 | EQ21: -0.11827632 | ER21: 0.042402379 | ES21: 0.11899188 | ET21: 0.10232183 | EU21: 0.14999369 | EV21: -0.075588511 | EW21: -0.18028259 | EX21: 0.034256176 | EY21: -0.052351445 | EZ21: -0.037801705 | FA21: -0.048599879 | FB21: -0.085885029 | FC21: 0.24342501 | FD21: 0.28117193 | FE21: 0.097720407 | FF21: -0.0060913742 | FG21: -0.021039621 | FH21: 0.20905065 | FI21: -0.073801043 | FJ21: -0.080101927 | FK21: 0.12073444 | FL21: 0.27037632 | FM21: 0.55515724
B22: 0.079856382 | C22: 0.25421859 | D22: 0.24826763 | E22: -0.18831637 | F22: 0.10476645 | G22: 0.1124374 | H22: 0.13151349 | I22: -0.1824347 | J22: 0.15670271 | K22: 0.27462167 | L22: 0.1522281 | M22: 0.17565563 | N22: 0.063348462 | O22: 0.1424753 | P22: -0.043810649 | Q22: 0.24989279 | R22: 0.37196598 | S22: 0.27333074 | T22: 0.3461038 | U22: 0.19667525 | V22: 0.92018692 | AQ22: 0 | AR22: 0 | AS22: 0 | AT22: 0 | AU22: 0 | AV22: 0 | AW22: 0 | AX22: 0 | AY22: 0 | AZ22: 0 | BA22: 0 | BB22: 0 | BC22: 0 | BD22: 0 | BE22: 0 | BF22: 0 | BG22: 0 | BH22: 0 | BI22: 0 | BJ22: 0 | BK22: 0.92018692 | BL22: 0.53846041 | BM22: 0.061522844 | BN22: 0.14053427 | BO22: 0.34292614 | BP22: 0.39871452 | BQ22: 0.1145161 | BR22: 0.2690742 | BS22: 0.15545562 | BT22: 0.055273894 | BU22: 0.1661418 | BV22: 0.20296089 | BW22: 0.18371405 | BX22: 0.036500068 | BY22: 0.02900691 | BZ22: 0.038351243 | CA22: 0.28448016 | CB22: 0.055325325 | CC22: 0.048955498 | CJ22: 0.079856382 | CK22: 0.25421859 | CL22: 0.24826763 | CM22: -0.18831637 | CN22: 0.10476645 | CO22: 0.1124374 | CP22: 0.13151349 | CQ22: -0.1824347 | CR22: 0.15670271 | CS22: 0.27462167 | CT22: 0.1522281 | CU22: 0.17565563 | CV22: 0.063348462 | CW22: 0.1424753 | CX22: -0.043810649 | CY22: 0.24989279 | CZ22: 0.37196598 | DA22: 0.27333074 | DB22: 0.3461038 | DC22: 0.19667525 | DD22: 0.92018692 | DE22: 0.53846041 | DF22: 0.061522844 | DG22: 0.14053427 | DH22: 0.34292614 | DI22: 0.39871452 | DJ22: 0.1145161 | DK22: 0.2690742 | DL22: 0.15545562 | DM22: 0.055273894 | DN22: 0.1661418 | DO22: 0.20296089 | DP22: 0.18371405 | DQ22: 0.036500068 | DR22: 0.02900691 | DS22: 0.038351243 | DT22: 0.28448016 | DU22: 0.055325325 | DV22: 0.048955498 | DZ22: 0.62171402 | EA22: 0.050171017 | EB22: 0.29716587 | EC22: 0.0078263741 | ED22: 0.027054785 | EE22: -0.11708977 | EF22: -0.060489276 | EG22: 0.21099467 | EH22: -0.076717446 | EI22: -0.038631973 | EJ22: 0.13065011 | EK22: 0.17991718 | EL22: 0.1584645 | EM22: -0.1037432 | EN22: 0.12174106 | EO22: 0.021174495 | EP22: -0.064238279 | EQ22: 0.022085053 | ER22: -0.11602403 | ES22: 0.16328882 | ET22: 0.059324733 | EU22: 0.061116137 | EV22: -0.2350069 | EW22: 0.14055622 | EX22: -0.6788283 | EY22: -0.097166495 | EZ22: -0.17188049 | FA22: 0.17065319 | FB22: 0.12519249 | FC22: 0.14892452 | FD22: -0.027053872 | FE22: 0.084674758 | FF22: 0.068856172 | FG22: -0.0070414048 | FH22: -0.10931472 | FI22: 0.048165777 | FJ22: 0.031128455 | FK22: -0.086029172 | FL22: 0.048299338 | FM22: -0.084407213
B23: 0.31227038 | C23: 0.771932 | D23: 1.1066465 | E23: 0.77889403 | F23: 0.83775942 | G23: 0.56667859 | H23: 0.36976096 | I23: 0.43360889 | J23: 0.9867346 | K23: 0.9109478 | L23: 0.47322393 | M23: 0.98136839 | N23: 0.39805486 | O23: 0.58452156 | P23: 0.69435733 | Q23: 0.63760392 | R23: 1.196812 | S23: 0.87631331 | T23: 1.1111551 | U23: 0.41057693 | V23: 0.53846041 | W23: 1.7534153 | AQ23: 0 | AR23: 0 | AS23: 0 | AT23: 0 | AU23: 0 | AV23: 0 | AW23: 0 | AX23: 0 | AY23: 0 | AZ23: 0 | BA23: 0 | BB23: 0 | BC23: 0 | BD23: 0 | BE23: 0 | BF23: 0 | BG23: 0 | BH23: 0 | BI23: 0 | BJ23: 0 | BK23: 0 | BL23: 1.7534153 | BM23: 0.6499593 | BN23: 0.778427 | BO23: 0.94960375 | BP23: 1.1284416 | BQ23: 0.48449533 | BR23: 0.80856837 | BS23: 0.62833451 | BT23: 0.19010467 | BU23: 0.57327241 | BV23: 0.78352941 | BW23: 0.86268759 | BX23: 0.18322545 | BY23: 0.3797829 | BZ23: 0.27480658 | CA23: 0.96959631 | CB23: 0.45387458 | CC23: 0.0074751156 | CJ23: 0.31227038 | CK23: 0.771932 | CL23: 1.1066465 | CM23: 0.77889403 | CN23: 0.83775942 | CO23: 0.56667859 | CP23: 0.36976096 | CQ23: 0.43360889 | CR23: 0.9867346 | CS23: 0.9109478 | CT23: 0.47322393 | CU23: 0.98136839 | CV23: 0.39805486 | CW23: 0.58452156 | CX23: 0.69435733 | CY23: 0.63760392 | CZ23: 1.196812 | DA23: 0.87631331 | DB23: 1.1111551 | DC23: 0.41057693 | DD23: 0.53846041 | DE23: 1.7534153 | DF23: 0.6499593 | DG23: 0.778427 | DH23: 0.94960375 | DI23: 1.1284416 | DJ23: 0.48449533 | DK23: 0.80856837 | DL23: 0.62833451 | DM23: 0.19010467 | DN23: 0.57327241 | DO23: 0.78352941 | DP23: 0.86268759 | DQ23: 0.18322545 | DR23: 0.3797829 | DS23: 0.27480658 | DT23: 0.96959631 | DU23: 0.45387458 | DV23: 0.0074751156 | DZ23: 0.54981164 | EA23: 0.042206066 | EB23: -0.071380008 | EC23: 0.09317835 | ED23: -0.31173931 | EE23: 0.09937994 | EF23: 0.30453756 | EG23: -0.047002279 | EH23: 0.027705644 | EI23: 0.14826723 | EJ23: 0.0063007741 | EK23: 0.072450681 | EL23: 0.15146378 | EM23: -0.16367341 | EN23: 0.32190311 | EO23: 0.074285001 | EP23: -0.078552107 | EQ23: 0.063350776 | ER23: 0.097813352 | ES23: 0.0061455887 | ET23: -0.051796935 | EU23: 0.035406918 | EV23: -0.42139437 | EW23: -0.15085189 | EX23: 0.10048841 | EY23: 0.13047039 | EZ23: -0.044390356 | FA23: -0.34584521 | FB23: 0.12164698 | FC23: 0.1594456 | FD23: -0.28029945 | FE23: -0.17378214 | FF23: 0.060423892 | FG23: -0.055299013 | FH23: -0.17512916 | FI23: -0.056084051 | FJ23: 0.020455214 | FK23: -0.00082595364 | FL23: -0.1566346 | FM23: 0.091101794
B24: 0.14618714 | C24: 0.27963989 | D24: 0.62180616 | E24: 0.3319135 | F24: 0.91927999 | G24: 0.37738795 | H24: 0.23811404 | I24: 0.045434917 | J24: 1.0922759 | K24: 0.44374873 | L24: 0.21717602 | M24: 0.5238764 | N24: 0.23734662 | O24: 0.2858143 | P24: 0.36694941 | Q24: 0.25764321 | R24: 0.55396548 | S24: 0.40046102 | T24: 0.57111171 | U24: 0.17753907 | V24: 0.061522844 | W24: 0.6499593 | X24: 1.221167 | AQ24: 0 | AR24: 0 | AS24: 0 | AT24: 0 | AU24: 0 | AV24: 0 | AW24: 0 | AX24: 0 | AY24: 0 | AZ24: 0 | BA24: 0 | BB24: 0 | BC24: 0 | BD24: 0 | BE24: 0 | BF24: 0 | BG24: 0 | BH24: 0 | BI24: 0 | BJ24: 0 | BK24: 0 | BL24: 0 | BM24: 1.221167 | BN24: 0.32507736 | BO24: 0.047262797 | BP24: 0.41629447 | BQ24: 0.23777919 | BR24: 0.2710885 | BS24: 0.32268053 | BT24: 0.1141091 | BU24: 0.3031421 | BV24: 0.24024342 | BW24: 0.41995378 | BX24: 0.14540492 | BY24: 0.19977593 | BZ24: 0.23758968 | CA24: 0.51460937 | CB24: 0.30322403 | CC24: -0.022757399 | CJ24: 0.14618714 | CK24: 0.27963989 | CL24: 0.62180616 | CM24: 0.3319135 | CN24: 0.91927999 | CO24: 0.37738795 | CP24: 0.23811404 | CQ24: 0.045434917 | CR24: 1.0922759 | CS24: 0.44374873 | CT24: 0.21717602 | CU24: 0.5238764 | CV24: 0.23734662 | CW24: 0.2858143 | CX24: 0.36694941 | CY24: 0.25764321 | CZ24: 0.55396548 | DA24: 0.40046102 | DB24: 0.57111171 | DC24: 0.17753907 | DD24: 0.061522844 | DE24: 0.6499593 | DF24: 1.221167 | DG24: 0.32507736 | DH24: 0.047262797 | DI24: 0.41629447 | DJ24: 0.23777919 | DK24: 0.2710885 | DL24: 0.32268053 | DM24: 0.1141091 | DN24: 0.3031421 | DO24: 0.24024342 | DP24: 0.41995378 | DQ24: 0.14540492 | DR24: 0.19977593 | DS24: 0.23758968 | DT24: 0.51460937 | DU24: 0.30322403 | DV24: -0.022757399 | DZ24: 0.52569992 | EA24: 0.13172716 | EB24: -0.076136303 | EC24: 0.1435225 | ED24: -0.2013225 | EE24: -0.019509766 | EF24: -0.19682402 | EG24: 0.030491177 | EH24: 0.12375796 | EI24: 0.20265398 | EJ24: -0.30068145 | EK24: 0.11599404 | EL24: -0.43026595 | EM24: 0.19253654 | EN24: 0.30976482 | EO24: 0.099036194 | EP24: -0.0021891986 | EQ24: -0.045317458 | ER24: -0.015863268 | ES24: 0.0049692408 | ET24: 0.13484792 | EU24: 0.02301411 | EV24: -0.018776474 | EW24: 0.015716748 | EX24: 0.062029552 | EY24: 0.23527077 | EZ24: -0.27555378 | FA24: 0.33904254 | FB24: -0.080613518 | FC24: 0.0010100128 | FD24: 0.04294124 | FE24: -0.012652225 | FF24: 0.21013223 | FG24: 0.1264769 | FH24: -0.1353661 | FI24: -0.099756404 | FJ24: -0.0412529 | FK24: -0.09642115 | FL24: 0.077499242 | FM24: -0.042403006
B25: 0.17072622 | C25: 0.41055022 | D25: 0.57884508 | E25: 0.46392601 | F25: 0.65852657 | G25: 0.34413926 | H25: 0.18253549 | I25: 0.29975694 | J25: 0.68914961 | K25: 0.46235224 | L25: 0.3054568 | M25: 0.47012117 | N25: 0.25194945 | O25: 0.31818955 | P25: 0.35443177 | Q25: 0.29763639 | R25: 0.61945008 | S25: 0.46851242 | T25: 0.51546956 | U25: 0.18496357 | V25: 0.14053427 | W25: 0.778427 | X25: 0.32507736 | Y25: 0.88670089 | AQ25: 0 | AR25: 0 | AS25: 0 | AT25: 0 | AU25: 0 | AV25: 0 | AW25: 0 | AX25: 0 | AY25: 0 | AZ25: 0 | BA25: 0 | BB25: 0 | BC25: 0 | BD25: 0 | BE25: 0 | BF25: 0 | BG25: 0 | BH25: 0 | BI25: 0 | BJ25: 0 | BK25: 0 | BL25: 0 | BM25: 0 | BN25: 0.88670089 | BO25: 0.34627418 | BP25: 0.56537028 | BQ25: 0.13281105 | BR25: 0.44855668 | BS25: 0.35354061 | BT25: 0.098871505 | BU25: 0.29752274 | BV25: 0.54433419 | BW25: 0.49978607 | BX25: 0.1228934 | BY25: 0.23969651 | BZ25: 0.12957518 | CA25: 0.54409752 | CB25: 0.24139162 | CC25: -0.0057161321 | CJ25: 0.17072622 | CK25: 0.41055022 | CL25: 0.57884508 | CM25: 0.46392601 | CN25: 0.65852657 | CO25: 0.34413926 | CP25: 0.18253549 | CQ25: 0.29975694 | CR25: 0.68914961 | CS25: 0.46235224 | CT25: 0.3054568 | CU25: 0.47012117 | CV25: 0.25194945 | CW25: 0.31818955 | CX25: 0.35443177 | CY25: 0.29763639 | CZ25: 0.61945008 | DA25: 0.46851242 | DB25: 0.51546956 | DC25: 0.18496357 | DD25: 0.14053427 | DE25: 0.778427 | DF25: 0.32507736 | DG25: 0.88670089 | DH25: 0.34627418 | DI25: 0.56537028 | DJ25: 0.13281105 | DK25: 0.44855668 | DL25: 0.35354061 | DM25: 0.098871505 | DN25: 0.29752274 | DO25: 0.54433419 | DP25: 0.49978607 | DQ25: 0.1228934 | DR25: 0.23969651 | DS25: 0.12957518 | DT25: 0.54409752 | DU25: 0.24139162 | DV25: -0.0057161321 | DZ25: 0.4844005 | EA25: 0.039197487 | EB25: 0.044494012 | EC25: 0.036779102 | ED25: -0.011629778 | EE25: -0.023870517 | EF25: 0.0013833263 | EG25: 0.12860782 | EH25: -0.25045157 | EI25: -0.13655466 | EJ25: 0.0088337844 | EK25: 0.20769847 | EL25: -0.036703164 | EM25: 0.19843933 | EN25: -0.23138178 | EO25: -0.1318596 | EP25: -0.16423614 | EQ25: 0.015204612 | ER25: -0.11744244 | ES25: 0.088378401 | ET25: 0.2066947 | EU25: -0.085145049 | EV25: -0.1753079 | EW25: 0.081626596 | EX25: 0.285783 | EY25: 0.030674521 | EZ25: -0.074835944 | FA25: -0.17480301 | FB25: 0.099273691 | FC25: 0.12207855 | FD25: -0.32982919 | FE25: -0.002965261 | FF25: 0.048370786 | FG25: 0.17243871 | FH25: 0.22147391 | FI25: 0.064834237 | FJ25: -0.11764119 | FK25: -0.16928084 | FL25: 0.45495127 | FM25: -0.13542249
